---
title: "Active Jobが失敗した場合のリトライについてテストする"
draft: false
tags: ["rails","ruby","rspec"]
private: false
slug: "990bd1dc-2f44-46fa-9fa6-91b5914e7669"
date: "2020-03-06T19:49:43+09:00"
lastmod: "2020-03-09T11:18:12+09:00"
keywords: ["rails","ruby","rspec","ベジプロ","プログ","プログラム"]
# headless: true
---

# 解決
`described_class.perform_later rescue nil`

```rb
RSpec.describe MyJob, type: :job do
  include ActiveJob::TestHelper

  context 'when `MyError` is raised' do
    before do
      allow_any_instance_of(described_class).to receive(:perform).and_raise(MyError.new)
    end

    it 'makes 4 attempts' do
      assert_performed_jobs 4 do
        described_class.perform_later rescue nil
      end
    end

    it 'does something in the `retry_on` block' do
      expect(Something).to receive(:something)

      perform_enqueued_jobs do
        described_class.perform_later rescue nil
      end
    end
  end
end
```

```!
perform_nowでは再実施は発生しないよう
```

## 疑問
`rescue nil` を付与しなくても動きそう？

> [ruby on rails - How to properly test ActiveJob's retry_on method with rspec? - Stack Overflow](https://stackoverflow.com/questions/51773822/how-to-properly-test-activejobs-retry-on-method-with-rspec)
